Traceback (most recent call last):
  File "/opt/conda/bin/mriqc", line 8, in <module>
    sys.exit(main())
  File "/opt/conda/lib/python3.8/site-packages/mriqc/cli/run.py", line 98, in main
    mriqc_wf.run(**config.nipype.get_plugin())
  File "/opt/conda/lib/python3.8/site-packages/nipype/pipeline/engine/workflows.py", line 638, in run
    runner.run(execgraph, updatehash=updatehash, config=self.config)
  File "/opt/conda/lib/python3.8/site-packages/nipype/pipeline/plugins/base.py", line 164, in run
    self._clean_queue(jobid, graph, result=result)
  File "/opt/conda/lib/python3.8/site-packages/nipype/pipeline/plugins/base.py", line 227, in _clean_queue
    raise RuntimeError("".join(result["traceback"]))
RuntimeError: Traceback (most recent call last):
  File "/opt/conda/lib/python3.8/site-packages/nipype/interfaces/base/core.py", line 428, in run
    runtime = self._run_interface(runtime)
  File "/opt/conda/lib/python3.8/site-packages/nipype/algorithms/confounds.py", line 921, in _run_interface
    [
  File "/opt/conda/lib/python3.8/site-packages/nipype/algorithms/confounds.py", line 922, in <listcomp>
    vol.get_fdata(dtype=np.float32).reshape(vol.shape[:3] + (-1,))
  File "/opt/conda/lib/python3.8/site-packages/nibabel/dataobj_images.py", line 355, in get_fdata
    data = np.asanyarray(self._dataobj, dtype=dtype)
  File "/opt/conda/lib/python3.8/site-packages/nibabel/arrayproxy.py", line 391, in __array__
    arr = self._get_scaled(dtype=dtype, slicer=())
  File "/opt/conda/lib/python3.8/site-packages/nibabel/arrayproxy.py", line 360, in _get_scaled
    scaled = scaled.astype(np.promote_types(scaled.dtype, dtype), copy=False)
numpy.core._exceptions._ArrayMemoryError: Unable to allocate 1.31 GiB for an array with shape (188, 188, 46, 216) and data type float32

During handling of the above exception, another exception occurred:

Traceback (most recent call last):
  File "/opt/conda/lib/python3.8/site-packages/nipype/pipeline/plugins/multiproc.py", line 67, in run_node
    result["result"] = node.run(updatehash=updatehash)
  File "/opt/conda/lib/python3.8/site-packages/nipype/pipeline/engine/nodes.py", line 516, in run
    result = self._run_interface(execute=True)
  File "/opt/conda/lib/python3.8/site-packages/nipype/pipeline/engine/nodes.py", line 635, in _run_interface
    return self._run_command(execute)
  File "/opt/conda/lib/python3.8/site-packages/nipype/pipeline/engine/nodes.py", line 741, in _run_command
    result = self._interface.run(cwd=outdir)
  File "/opt/conda/lib/python3.8/site-packages/nipype/interfaces/base/core.py", line 445, in run
    runtime.traceback_args = ("\n".join(["%s" % arg for arg in exc_args]),)
  File "/opt/conda/lib/python3.8/site-packages/nipype/interfaces/base/core.py", line 445, in <listcomp>
    runtime.traceback_args = ("\n".join(["%s" % arg for arg in exc_args]),)
TypeError: not all arguments converted during string formatting

