Traceback (most recent call last):
  File "/opt/conda/bin/mriqc", line 8, in <module>
    sys.exit(main())
  File "/opt/conda/lib/python3.8/site-packages/mriqc/cli/run.py", line 98, in main
    mriqc_wf.run(**config.nipype.get_plugin())
  File "/opt/conda/lib/python3.8/site-packages/nipype/pipeline/engine/workflows.py", line 638, in run
    runner.run(execgraph, updatehash=updatehash, config=self.config)
  File "/opt/conda/lib/python3.8/site-packages/nipype/pipeline/plugins/base.py", line 164, in run
    self._clean_queue(jobid, graph, result=result)
  File "/opt/conda/lib/python3.8/site-packages/nipype/pipeline/plugins/base.py", line 227, in _clean_queue
    raise RuntimeError("".join(result["traceback"]))
RuntimeError: Traceback (most recent call last):
  File "/opt/conda/lib/python3.8/site-packages/nipype/interfaces/base/core.py", line 428, in run
    runtime = self._run_interface(runtime)
  File "/opt/conda/lib/python3.8/site-packages/mriqc/interfaces/viz.py", line 94, in _run_interface
    plot_segmentation(
  File "/opt/conda/lib/python3.8/site-packages/mriqc/viz/utils.py", line 564, in plot_segmentation
    disp = plot_anat(
  File "/opt/conda/lib/python3.8/site-packages/nilearn/plotting/img_plotting.py", line 497, in plot_anat
    anat_img, black_bg, anat_vmin, anat_vmax = _load_anat(
  File "/opt/conda/lib/python3.8/site-packages/nilearn/plotting/img_plotting.py", line 416, in _load_anat
    anat_img = _utils.check_niimg_3d(anat_img)
  File "/opt/conda/lib/python3.8/site-packages/nilearn/_utils/niimg_conversions.py", line 338, in check_niimg_3d
    return check_niimg(niimg, ensure_ndim=3, dtype=dtype)
  File "/opt/conda/lib/python3.8/site-packages/nilearn/_utils/niimg_conversions.py", line 283, in check_niimg
    niimg = load_niimg(niimg, dtype=dtype)
  File "/opt/conda/lib/python3.8/site-packages/nilearn/_utils/niimg.py", line 134, in load_niimg
    dtype = _get_target_dtype(_get_data(niimg).dtype, dtype)
  File "/opt/conda/lib/python3.8/site-packages/nilearn/_utils/niimg.py", line 24, in _get_data
    data = np.asanyarray(img._dataobj)
  File "/opt/conda/lib/python3.8/site-packages/nibabel/arrayproxy.py", line 391, in __array__
    arr = self._get_scaled(dtype=dtype, slicer=())
  File "/opt/conda/lib/python3.8/site-packages/nibabel/arrayproxy.py", line 358, in _get_scaled
    scaled = apply_read_scaling(self._get_unscaled(slicer=slicer), scl_slope, scl_inter)
  File "/opt/conda/lib/python3.8/site-packages/nibabel/volumeutils.py", line 961, in apply_read_scaling
    arr = arr + inter
numpy.core._exceptions._ArrayMemoryError: Unable to allocate 1.56 GiB for an array with shape (512, 640, 640) and data type float64

During handling of the above exception, another exception occurred:

Traceback (most recent call last):
  File "/opt/conda/lib/python3.8/site-packages/nipype/pipeline/plugins/multiproc.py", line 67, in run_node
    result["result"] = node.run(updatehash=updatehash)
  File "/opt/conda/lib/python3.8/site-packages/nipype/pipeline/engine/nodes.py", line 516, in run
    result = self._run_interface(execute=True)
  File "/opt/conda/lib/python3.8/site-packages/nipype/pipeline/engine/nodes.py", line 635, in _run_interface
    return self._run_command(execute)
  File "/opt/conda/lib/python3.8/site-packages/nipype/pipeline/engine/nodes.py", line 741, in _run_command
    result = self._interface.run(cwd=outdir)
  File "/opt/conda/lib/python3.8/site-packages/nipype/interfaces/base/core.py", line 445, in run
    runtime.traceback_args = ("\n".join(["%s" % arg for arg in exc_args]),)
  File "/opt/conda/lib/python3.8/site-packages/nipype/interfaces/base/core.py", line 445, in <listcomp>
    runtime.traceback_args = ("\n".join(["%s" % arg for arg in exc_args]),)
TypeError: not all arguments converted during string formatting

