Traceback (most recent call last):
  File "/opt/conda/bin/mriqc", line 8, in <module>
    sys.exit(main())
  File "/opt/conda/lib/python3.8/site-packages/mriqc/cli/run.py", line 98, in main
    mriqc_wf.run(**config.nipype.get_plugin())
  File "/opt/conda/lib/python3.8/site-packages/nipype/pipeline/engine/workflows.py", line 638, in run
    runner.run(execgraph, updatehash=updatehash, config=self.config)
  File "/opt/conda/lib/python3.8/site-packages/nipype/pipeline/plugins/base.py", line 164, in run
    self._clean_queue(jobid, graph, result=result)
  File "/opt/conda/lib/python3.8/site-packages/nipype/pipeline/plugins/base.py", line 227, in _clean_queue
    raise RuntimeError("".join(result["traceback"]))
RuntimeError: Traceback (most recent call last):
  File "/opt/conda/lib/python3.8/site-packages/nipype/interfaces/base/core.py", line 428, in run
    runtime = self._run_interface(runtime)
  File "/opt/conda/lib/python3.8/site-packages/mriqc/interfaces/viz.py", line 94, in _run_interface
    plot_segmentation(
  File "/opt/conda/lib/python3.8/site-packages/mriqc/viz/utils.py", line 564, in plot_segmentation
    disp = plot_anat(
  File "/opt/conda/lib/python3.8/site-packages/nilearn/plotting/img_plotting.py", line 506, in plot_anat
    display = plot_img(anat_img, cut_coords=cut_coords,
  File "/opt/conda/lib/python3.8/site-packages/nilearn/plotting/img_plotting.py", line 306, in plot_img
    display = _plot_img_with_bg(
  File "/opt/conda/lib/python3.8/site-packages/nilearn/plotting/img_plotting.py", line 185, in _plot_img_with_bg
    display = display_factory(display_mode)(
  File "/opt/conda/lib/python3.8/site-packages/nilearn/plotting/displays.py", line 646, in init_with_figure
    cut_coords = cls.find_cut_coords(img, threshold, cut_coords)
  File "/opt/conda/lib/python3.8/site-packages/nilearn/plotting/displays.py", line 1736, in find_cut_coords
    cut_coords = find_cut_slices(img,
  File "/opt/conda/lib/python3.8/site-packages/nilearn/plotting/find_cuts.py", line 307, in find_cut_slices
    data = _smooth_array(data, affine, fwhm='fast')
  File "/opt/conda/lib/python3.8/site-packages/nilearn/image/image.py", line 230, in _smooth_array
    arr = _fast_smooth_array(arr)
  File "/opt/conda/lib/python3.8/site-packages/nilearn/image/image.py", line 151, in _fast_smooth_array
    weighted_arr = neighbor_weight * arr
numpy.core._exceptions._ArrayMemoryError: Unable to allocate 800. MiB for an array with shape (512, 640, 640) and data type float32

During handling of the above exception, another exception occurred:

Traceback (most recent call last):
  File "/opt/conda/lib/python3.8/site-packages/nipype/pipeline/plugins/multiproc.py", line 67, in run_node
    result["result"] = node.run(updatehash=updatehash)
  File "/opt/conda/lib/python3.8/site-packages/nipype/pipeline/engine/nodes.py", line 516, in run
    result = self._run_interface(execute=True)
  File "/opt/conda/lib/python3.8/site-packages/nipype/pipeline/engine/nodes.py", line 635, in _run_interface
    return self._run_command(execute)
  File "/opt/conda/lib/python3.8/site-packages/nipype/pipeline/engine/nodes.py", line 741, in _run_command
    result = self._interface.run(cwd=outdir)
  File "/opt/conda/lib/python3.8/site-packages/nipype/interfaces/base/core.py", line 445, in run
    runtime.traceback_args = ("\n".join(["%s" % arg for arg in exc_args]),)
  File "/opt/conda/lib/python3.8/site-packages/nipype/interfaces/base/core.py", line 445, in <listcomp>
    runtime.traceback_args = ("\n".join(["%s" % arg for arg in exc_args]),)
TypeError: not all arguments converted during string formatting

